<robot
  name="elfin3" xmlns:xacro="http://www.ros.org/wiki/xacro">
  
  <xacro:include filename="$(find elfin_description)/urdf/materials.xacro" />
  
  <xacro:include filename="$(find elfin_description)/urdf/modules/modules.gazebo" />
  
  <xacro:include filename="$(find elfin_description)/urdf/modules/modules_transmission.xacro" />
  
  <xacro:property name="PI" value="3.1415926535897931"/>
  
  <xacro:property name="density" value="3.09"/>
  
  <link name="world"/>
  
  <joint name="world_base" type="fixed">
    <origin
      xyz="0 0 0"
      rpy="0 0 0" />
    <parent
      link="world" />
    <child
      link="elfin_base" />
  </joint>
  
  <link name="elfin_base"/>
  
  <joint name="elfin_module_base_joint" type="fixed">
    <origin
      xyz="0 0 0.2"
      rpy="0 0 0" />
    <parent
      link="elfin_base" />
    <child
      link="elfin_module_link" />
  </joint>
  
<link
    name="elfin_module_link">
    <inertial>
      <origin
        xyz="-0.055318 3.0677E-06 0.099673"
        rpy="0 0 0" />
      <mass value="${0.37026646381*density}"/>
      <inertia
      ixx="${0.00238279*density}" ixy="${0.00082955*density}" ixz="${1.1e-07*density}"
      iyy="${0.00095758*density}" iyz="${-3.2e-07*density}"
      izz="${0.00285161*density}"/>
    </inertial>
    <visual>
      <origin
        xyz="0 0 0"
        rpy="0 0 0" />
      <geometry>
        <mesh
          filename="package://elfin_description/meshes/elfin3/elfin_link4.STL" />
      </geometry>
      <material
        name="metal_grey"/>
    </visual>
    <collision>
      <origin
        xyz="0 0 0"
        rpy="0 0 0" />
      <geometry>
        <mesh
          filename="package://elfin_description/meshes/elfin3/elfin_link4.STL" />
      </geometry>
    </collision>
  </link>
  

  <link
    name="elfin_module_link1">
    <inertial>
      <origin
        xyz="3.7144E-06 0.039279 -0.043638"
        rpy="0 0 0" />
      <mass value="${0.807027243448*density}"/>
      <inertia
      ixx="${0.00193719*density}" ixy="${0.00047145*density}" ixz="${2e-08*density}"
      iyy="${0.00112857*density}" iyz="${-1.1e-07*density}"
      izz="${0.00245655*density}"/>
    </inertial>
    <visual>
      <origin
        xyz="0 0 0"
        rpy="0 0 0" />
      <geometry>
        <mesh
          filename="package://elfin_description/meshes/elfin3/elfin_link5.STL" />
      </geometry>
      <material
        name="metal"/>
    </visual>
    <collision>
      <origin
        xyz="0 0 0"
        rpy="0 0 0" />
      <geometry>
        <mesh
          filename="package://elfin_description/meshes/elfin3/elfin_link5.STL" />
      </geometry>
    </collision>
  </link>
  <joint
    name="elfin_module_joint1"
    type="revolute">
     <origin
      xyz="-0.06025 0 0.219"
      rpy="1.5708 0 -1.5708" />
    <parent
      link="elfin_module_link" />
    <child
      link="elfin_module_link1" />
     <axis
      xyz="0 0 -1" />
    <limit
      lower="-2.56"
      upper="2.56"
      effort="34"
      velocity="1.57" />
  </joint>


<link
    name="elfin_module_link2">
   <inertial>
      <origin
        xyz="-0.0070896 -0.00016176 0.034853"
        rpy="0 0 0" />
      <mass value="${0.147312*density}"/>
      <inertia
      ixx="${0.00019407*density}" ixy="${1.4e-06*density}" ixz="${-2.89e-06*density}"
      iyy="${0.00019592*density}" iyz="${5e-08*density}"
      izz="${0.00019496*density}"/>
    </inertial>
    <visual>
      <origin
        xyz="0 0 0"
        rpy="0 0 0" />
      <geometry>
        <mesh
          filename="package://elfin_description/meshes/elfin3/elfin_link6.STL" />
      </geometry>
      <material
        name="metal_white"/>
    </visual>
    <collision>
      <origin
        xyz="0 0 0"
        rpy="0 0 0" />
      <geometry>
        <mesh
          filename="package://elfin_description/meshes/elfin3/elfin_link6.STL" />
      </geometry>
    </collision>
  </link>
  <joint
    name="elfin_module_joint2"
    type="revolute">
   <origin
      xyz="0 0.10075 -0.06025"
      rpy="0 1.5645 1.5734" />
    <parent
      link="elfin_module_link1" />
    <child
      link="elfin_module_link2" />
     <axis
      xyz="0 0 -1" />
    <limit
      lower="-3.14"
      upper="3.14"
      effort="34"
      velocity="1.57" />
  </joint>
      
</robot>
