<robot
  name="elfin10" xmlns:xacro="http://www.ros.org/wiki/xacro">
  
  <xacro:include filename="$(find elfin_description)/urdf/materials.xacro" />
  
  <xacro:include filename="$(find elfin_description)/urdf/elfin_robot.gazebo" />
  
  <xacro:include filename="$(find elfin_description)/urdf/elfin_transmission.xacro" />
  
  <xacro:property name="PI" value="3.1415926535897931"/>
  
  <link name="world"/>
  
  <joint name="world_base" type="fixed">
    <origin
      xyz="0 0 0"
      rpy="0 0 0" />
    <parent
      link="world" />
    <child
      link="elfin_base_link" />
  </joint>
  
  <link name="elfin_base_link"/>
  
  <joint name="elfin_base_joint" type="fixed">
    <origin
      xyz="0 0 0"
      rpy="0 0 ${PI/2}" />
    <parent
      link="elfin_base_link" />
    <child
      link="elfin_base" />
  </joint>
  
  <link
    name="elfin_base">
    <inertial>
      <origin
        xyz="0.000308020598430213 0.027286204143835 -0.00272949562920981"
        rpy="0 0 0" />
      <mass
        value="0.885375178384734" />
      <inertia
        ixx="0.00286318889286201"
        ixy="3.45365039921659E-06"
        ixz="-1.62402262526516E-05"
        iyy="0.00535727192521691"
        iyz="-2.78342487667673E-05"
        izz="0.00303602788914978" />
    </inertial>
    <visual>
      <origin
        xyz="0 0 0"
        rpy="0 0 0" />
      <geometry>
        <mesh
          filename="package://elfin_description/meshes/elfin10/elfin_base.STL" />
      </geometry>
      <material
        name="metal_white"/>
    </visual>
    <collision>
      <origin
        xyz="0 0 0"
        rpy="0 0 0" />
      <geometry>
        <mesh
          filename="package://elfin_description/meshes/elfin10/elfin_base.STL" />
      </geometry>
    </collision>
  </link>
  <link
    name="elfin_link1">
    <inertial>
      <origin
        xyz="-0.025606009350082 0.195630799437867 1.98466916955487E-05"
        rpy="0 0 0" />
      <mass
        value="5.0663557884435" />
      <inertia
        ixx="0.0400804338380401"
        ixy="0.00849162788349833"
        ixz="-5.6134782300454E-06"
        iyy="0.0212587213618438"
        iyz="-2.4294887610495E-06"
        izz="0.0457568717782572" />
    </inertial>
    <visual>
      <origin
        xyz="0 0 0"
        rpy="0 0 0" />
      <geometry>
        <mesh
          filename="package://elfin_description/meshes/elfin10/elfin_link1.STL" />
      </geometry>
      <material
        name="metal"/>
    </visual>
    <collision>
      <origin
        xyz="0 0 0"
        rpy="0 0 0" />
      <geometry>
        <mesh
          filename="package://elfin_description/meshes/elfin10/elfin_link1.STL" />
      </geometry>
    </collision>
  </link>
  <joint
    name="elfin_joint1"
    type="revolute">
    <origin
      xyz="0 0 0"
      rpy="${PI/2} 0 0" />
    <parent
      link="elfin_base" />
    <child
      link="elfin_link1" />
    <axis
      xyz="0 1 0" />
    <limit
      lower="-3.14"
      upper="3.14"
      effort="120"
      velocity="1.57" />
  </joint>
  <link
    name="elfin_link2">
    <inertial>
      <origin
        xyz="-0.059127689307098 0.209937989447816 7.56723981552217E-06"
        rpy="0 0 0" />
      <mass
        value="1.67188352649654" />
      <inertia
        ixx="0.0525625660873116"
        ixy="-0.00220862698349637"
        ixz="-6.2414828525538E-07"
        iyy="0.00437200496167382"
        iyz="-9.38433431531435E-06"
        izz="0.0512001113698696" />
    </inertial>
    <visual>
      <origin
        xyz="0 0 0"
        rpy="0 0 0" />
      <geometry>
        <mesh
          filename="package://elfin_description/meshes/elfin10/elfin_link2.STL" />
      </geometry>
      <material
        name="metal_grey"/>
    </visual>
    <collision>
      <origin
        xyz="0 0 0"
        rpy="0 0 0" />
      <geometry>
        <mesh
          filename="package://elfin_description/meshes/elfin10/elfin_link2.STL" />
      </geometry>
    </collision>
  </link>
  <joint
    name="elfin_joint2"
    type="revolute">
    <origin
      xyz="-0.084469 0.26 0"
      rpy="0 0 0" />
    <parent
      link="elfin_link1" />
    <child
      link="elfin_link2" />
    <axis
      xyz="-1 0 0" />
    <limit
      lower="-2.35"
      upper="2.35"
      effort="120"
      velocity="1.57" />
  </joint>
  <link
    name="elfin_link3">
    <inertial>
      <origin
        xyz="0.0625123989669429 -0.052176807477553 2.64760976133438E-05"
        rpy="0 0 0" />
      <mass
        value="2.52856215211273" />
      <inertia
        ixx="0.012667847540505"
        ixy="0.00290607544164991"
        ixz="-1.47525213406371E-06"
        iyy="0.00711624913901914"
        iyz="-2.69674594651337E-06"
        izz="0.0150236128176268" />
    </inertial>
    <visual>
      <origin
        xyz="0 0 0"
        rpy="0 0 0" />
      <geometry>
        <mesh
          filename="package://elfin_description/meshes/elfin10/elfin_link3.STL" />
      </geometry>
      <material
        name="metal"/>
    </visual>
    <collision>
      <origin
        xyz="0 0 0"
        rpy="0 0 0" />
      <geometry>
        <mesh
          filename="package://elfin_description/meshes/elfin10/elfin_link3.STL" />
      </geometry>
    </collision>
  </link>
  <joint
    name="elfin_joint3"
    type="revolute">
    <origin
      xyz="0 0.48 0"
      rpy="${PI} 0 0" />
    <parent
      link="elfin_link2" />
    <child
      link="elfin_link3" />
    <axis
      xyz="1 0 0" />
    <limit
      lower="-2.61"
      upper="2.61"
      effort="120"
      velocity="1.57" />
  </joint>
  <link
    name="elfin_link4">
    <inertial>
      <origin
        xyz="-0.0655191412736019 0.17921070701944 1.42681979805022E-05"
        rpy="0 0 0" />
      <mass
        value="0.774714242593802" />
      <inertia
        ixx="0.0125887055785559"
        ixy="0.00311217340021864"
        ixz="4.28455933012487E-08"
        iyy="0.00273673242411354"
        iyz="6.42522589973016E-07"
        izz="0.0136908740275145" />
    </inertial>
    <visual>
      <origin
        xyz="0 0 0"
        rpy="0 0 0" />
      <geometry>
        <mesh
          filename="package://elfin_description/meshes/elfin10/elfin_link4.STL" />
      </geometry>
      <material
        name="metal_grey"/>
    </visual>
    <collision>
      <origin
        xyz="0 0 0"
        rpy="0 0 0" />
      <geometry>
        <mesh
          filename="package://elfin_description/meshes/elfin10/elfin_link4.STL" />
      </geometry>
    </collision>
  </link>
  <joint
    name="elfin_joint4"
    type="revolute">
    <origin
      xyz="0.084469 -0.12571 0"
      rpy="${-PI} 0 0" />
    <parent
      link="elfin_link3" />
    <child
      link="elfin_link4" />
    <axis
      xyz="0 1 0" />
    <limit
      lower="-3.14"
      upper="3.14"
      effort="120"
      velocity="1.57" />
  </joint>
  <link
    name="elfin_link5">
    <inertial>
      <origin
        xyz="-0.0175084997767369 -0.0377654900394784 -7.04779685984352E-06"
        rpy="0 0 0" />
      <mass
        value="1.07922052439642" />
      <inertia
        ixx="0.00298738623352246"
        ixy="0.000725824515360465"
        ixz="4.96155482882277E-07"
        iyy="0.00183400932518434"
        iyz="-2.66412614052824E-07"
        izz="0.00375395523653828" />
    </inertial>
    <visual>
      <origin
        xyz="0 0 0"
        rpy="0 0 0" />
      <geometry>
        <mesh
          filename="package://elfin_description/meshes/elfin10/elfin_link5.STL" />
      </geometry>
      <material
        name="metal"/>
    </visual>
    <collision>
      <origin
        xyz="0 0 0"
        rpy="0 0 0" />
      <geometry>
        <mesh
          filename="package://elfin_description/meshes/elfin10/elfin_link5.STL" />
      </geometry>
    </collision>
  </link>
  <joint
    name="elfin_joint5"
    type="revolute">
    <origin
      xyz="0 0.39429 0"
      rpy="${-PI} 0 0" />
    <parent
      link="elfin_link4" />
    <child
      link="elfin_link5" />
    <axis
      xyz="1 0 0" />
    <limit
      lower="-2.56"
      upper="2.56"
      effort="120"
      velocity="1.57" />
  </joint>
  <link
    name="elfin_link6">
    <inertial>
      <origin
        xyz="-0.0412046461038743 -0.870077360796272 -0.000195877685084774"
        rpy="0 0 0" />
      <mass
        value="12.0061109281425" />
      <inertia
        ixx="1.92519773999221"
        ixy="0.0176915240535981"
        ixz="7.99693876355251E-05"
        iyy="0.0649687530706708"
        iyz="-0.00114805616509498"
        izz="1.9561905498035" />
    </inertial>
    <visual>
      <origin
        xyz="0 0 0"
        rpy="0 0 0" />
      <geometry>
        <mesh
          filename="package://elfin_description/meshes/elfin10/elfin_link6.STL" />
      </geometry>
      <material
        name="metal_white"/>
    </visual>
    <collision>
      <origin
        xyz="0 0 0"
        rpy="0 0 0" />
      <geometry>
        <mesh
          filename="package://elfin_description/meshes/elfin10/elfin_link6.STL" />
      </geometry>
    </collision>
  </link>
  <joint
    name="elfin_joint6"
    type="revolute">
    <origin
      xyz="0 -0.111 0"
      rpy="${PI} 0 0" />
    <parent
      link="elfin_link5" />
    <child
      link="elfin_link6" />
    <axis
      xyz="0 1 0" />
    <limit
      lower="-3.14"
      upper="3.14"
      effort="120"
      velocity="1.57" />
  </joint>
  
  <link name="elfin_end_link"/>
  
  <joint name="elfin_end_joint" type="fixed">
    <origin
      xyz="0 0.089 0"
      rpy="${-PI/2} ${-PI/2} 0" />
    <parent
      link="elfin_link6" />
    <child
      link="elfin_end_link" />
  </joint>
  
  <link name="elfin_dummy_gripper"/>
  
  <joint name="elfin_dummy_joint" type="fixed">
    <origin
      xyz="0 0.109 0"
      rpy="${-PI/2} ${-PI/2} 0" />
    <parent
      link="elfin_link6" />
    <child
      link="elfin_dummy_gripper" />
  </joint>
  
</robot>
