<robot
  name="elfin5" xmlns:xacro="http://www.ros.org/wiki/xacro">
  
  <xacro:include filename="$(find elfin_description)/urdf/materials.xacro" />
  
  <xacro:include filename="$(find elfin_description)/urdf/elfin_robot.gazebo" />
  
  <xacro:include filename="$(find elfin_description)/urdf/elfin_transmission.xacro" />
  
  <xacro:property name="PI" value="3.1415926535897931"/>
  
  <link name="world"/>
  
  <joint name="world_base" type="fixed">
    <origin
      xyz="0 0 0"
      rpy="0 0 0" />
    <parent
      link="world" />
    <child
      link="elfin_base_link" />
  </joint>
  
  <link name="elfin_base_link"/>
  
  <joint name="elfin_base_joint" type="fixed">
    <origin
      xyz="0 0 0"
      rpy="0 0 ${PI/2}" />
    <parent
      link="elfin_base_link" />
    <child
      link="elfin_base" />
  </joint>
  
  <link
    name="elfin_base">
    <inertial>
      <origin
        xyz="0.000220821977982989 0.0255290818849933 -0.00134044659901771"
        rpy="0 0 0" />
      <mass value="0.05"/>
      <inertia
	  ixx="0.001" ixy="0.0" ixz="0.0"
	  iyy="0.001" iyz="0.0"
	  izz="0.001"/>
    </inertial>
    <visual>
      <origin
        xyz="0 0 0"
        rpy="0 0 0" />
      <geometry>
        <mesh
          filename="package://elfin_description/meshes/elfin5/elfin_base.STL" />
      </geometry>
      <material
        name="metal_white"/>
    </visual>
    <collision>
      <origin
        xyz="0 0 0"
        rpy="0 0 0" />
      <geometry>
        <mesh
          filename="package://elfin_description/meshes/elfin5/elfin_base.STL" />
      </geometry>
    </collision>
  </link>
  <link
    name="elfin_link1">
    <inertial>
      <origin
        xyz="-0.0218141046310325 0.138891728726282 1.31241816829816E-05"
        rpy="0 0 0" />
      <mass value="0.05"/>
      <inertia
	  ixx="0.001" ixy="0.0" ixz="0.0"
	  iyy="0.001" iyz="0.0"
	  izz="0.001"/>
    </inertial>
    <visual>
      <origin
        xyz="0 0 0"
        rpy="0 0 0" />
      <geometry>
        <mesh
          filename="package://elfin_description/meshes/elfin5/elfin_link1.STL" />
      </geometry>
      <material
        name="metal"/>
    </visual>
    <collision>
      <origin
        xyz="0 0 0"
        rpy="0 0 0" />
      <geometry>
        <mesh
          filename="package://elfin_description/meshes/elfin5/elfin_link1.STL" />
      </geometry>
    </collision>
  </link>
  <joint
    name="elfin_joint1"
    type="revolute">
    <origin
      xyz="0 0 0.03"
      rpy="${PI/2} 0 0" />
    <parent
      link="elfin_base" />
    <child
      link="elfin_link1" />
    <axis
      xyz="0 1 0" />
    <limit
      lower="-3.14"
      upper="3.14"
      effort="200"
      velocity="1.57" />
  </joint>
  <link
    name="elfin_link2">
    <inertial>
      <origin
        xyz="-0.0524295669840444 0.158140141659462 -1.74919824000372E-06"
        rpy="0 0 0" />
      <mass value="0.05"/>
      <inertia
	  ixx="0.001" ixy="0.0" ixz="0.0"
	  iyy="0.001" iyz="0.0"
	  izz="0.001"/>
    </inertial>
    <visual>
      <origin
        xyz="0 0 0"
        rpy="0 0 0" />
      <geometry>
        <mesh
          filename="package://elfin_description/meshes/elfin5/elfin_link2.STL" />
      </geometry>
      <material
        name="metal_grey"/>
    </visual>
    <collision>
      <origin
        xyz="0 0 0"
        rpy="0 0 0" />
      <geometry>
        <mesh
          filename="package://elfin_description/meshes/elfin5/elfin_link2.STL" />
      </geometry>
    </collision>
  </link>
  <joint
    name="elfin_joint2"
    type="revolute">
    <origin
      xyz="-0.078069 0.19 0"
      rpy="0 0 0" />
    <parent
      link="elfin_link1" />
    <child
      link="elfin_link2" />
    <axis
      xyz="-1 0 0" />
    <limit
      lower="-2.35"
      upper="2.35"
      effort="200"
      velocity="1.57" />
  </joint>
  <link
    name="elfin_link3">
    <inertial>
      <origin
        xyz="0.0586561082766824 -0.0414791884757505 -9.80549635387022E-06"
        rpy="0 0 0" />
      <mass value="0.05"/>
      <inertia
	  ixx="0.001" ixy="0.0" ixz="0.0"
	  iyy="0.001" iyz="0.0"
	  izz="0.001"/>
    </inertial>
    <visual>
      <origin
        xyz="0 0 0"
        rpy="0 0 0" />
      <geometry>
        <mesh
          filename="package://elfin_description/meshes/elfin5/elfin_link3.STL" />
      </geometry>
      <material
        name="metal"/>
    </visual>
    <collision>
      <origin
        xyz="0 0 0"
        rpy="0 0 0" />
      <geometry>
        <mesh
          filename="package://elfin_description/meshes/elfin5/elfin_link3.STL" />
      </geometry>
    </collision>
  </link>
  <joint
    name="elfin_joint3"
    type="revolute">
    <origin
      xyz="0 0.38 0"
      rpy="${PI} 0 0" />
    <parent
      link="elfin_link2" />
    <child
      link="elfin_link3" />
    <axis
      xyz="1 0 0" />
    <limit
      lower="-2.61"
      upper="2.61"
      effort="104"
      velocity="1.57" />
  </joint>
  <link
    name="elfin_link4">
    <inertial>
      <origin
        xyz="-0.0589525602581192 0.143654952750886 -4.64578965075454E-05"
        rpy="0 0 0" />
      <mass value="0.05"/>
      <inertia
	  ixx="0.001" ixy="0.0" ixz="0.0"
	  iyy="0.001" iyz="0.0"
	  izz="0.001"/>
    </inertial>
    <visual>
      <origin
        xyz="0 0 0"
        rpy="0 0 0" />
      <geometry>
        <mesh
          filename="package://elfin_description/meshes/elfin5/elfin_link4.STL" />
      </geometry>
      <material
        name="metal_grey"/>
    </visual>
    <collision>
      <origin
        xyz="0 0 0"
        rpy="0 0 0" />
      <geometry>
        <mesh
          filename="package://elfin_description/meshes/elfin5/elfin_link4.STL" />
      </geometry>
    </collision>
  </link>
  <joint
    name="elfin_joint4"
    type="revolute">
    <origin
      xyz="0.078069 -0.11342 0"
      rpy="${-PI} 0 0" />
    <parent
      link="elfin_link3" />
    <child
      link="elfin_link4" />
    <axis
      xyz="0 1 0" />
    <limit
      lower="-3.14"
      upper="3.14"
      effort="104"
      velocity="1.57" />
  </joint>
  <link
    name="elfin_link5">
    <inertial>
      <origin
        xyz="-0.0159722248323729 -0.0365908819941969 2.28756223330485E-06"
        rpy="0 0 0" />
      <mass value="0.05"/>
      <inertia
	  ixx="0.001" ixy="0.0" ixz="0.0"
	  iyy="0.001" iyz="0.0"
	  izz="0.001"/>
    </inertial>
    <visual>
      <origin
        xyz="0 0 0"
        rpy="0 0 0" />
      <geometry>
        <mesh
          filename="package://elfin_description/meshes/elfin5/elfin_link5.STL" />
      </geometry>
      <material
        name="metal"/>
    </visual>
    <collision>
      <origin
        xyz="0 0 0"
        rpy="0 0 0" />
      <geometry>
        <mesh
          filename="package://elfin_description/meshes/elfin5/elfin_link5.STL" />
      </geometry>
    </collision>
  </link>
  <joint
    name="elfin_joint5"
    type="revolute">
    <origin
      xyz="0 0.30658 0"
      rpy="${-PI} 0 0" />
    <parent
      link="elfin_link4" />
    <child
      link="elfin_link5" />
    <axis
      xyz="1 0 0" />
    <limit
      lower="-2.56"
      upper="2.56"
      effort="34"
      velocity="1.57" />
  </joint>
  <link
    name="elfin_link6">
    <inertial>
      <origin
        xyz="-0.0390479629436857 0.693839823742315 0.000123076547971226"
        rpy="0 0 0" />
      <mass value="0.05"/>
      <inertia
	  ixx="0.001" ixy="0.0" ixz="0.0"
	  iyy="0.001" iyz="0.0"
	  izz="0.001"/>
    </inertial>
    <visual>
      <origin
        xyz="0 0 0"
        rpy="0 0 0" />
      <geometry>
        <mesh
          filename="package://elfin_description/meshes/elfin5/elfin_link6.STL" />
      </geometry>
      <material
        name="metal_white"/>
    </visual>
    <collision>
      <origin
        xyz="0 0 0"
        rpy="0 0 0" />
      <geometry>
        <mesh
          filename="package://elfin_description/meshes/elfin5/elfin_link6.STL" />
      </geometry>
    </collision>
  </link>
  <joint
    name="elfin_joint6"
    type="revolute">
    <origin
      xyz="0 -0.1065 0"
      rpy="0 0 0" />
    <parent
      link="elfin_link5" />
    <child
      link="elfin_link6" />
    <axis
      xyz="0 -1 0" />
    <limit
      lower="-3.14"
      upper="3.14"
      effort="34"
      velocity="1.57" />
  </joint>
  
  <link name="elfin_end_link"/>
  
  <joint name="elfin_end_joint" type="fixed">
    <origin
      xyz="0 -0.0735 0"
      rpy="${PI/2} ${PI/2} 0" />
    <parent
      link="elfin_link6" />
    <child
      link="elfin_end_link" />
  </joint>
  
  <link name="elfin_dummy_gripper"/>
  
  <joint name="elfin_dummy_joint" type="fixed">
    <origin
      xyz="0 -0.0935 0"
      rpy="${PI/2} ${PI/2} 0" />
    <parent
      link="elfin_link6" />
    <child
      link="elfin_dummy_gripper" />
  </joint>
  
</robot>
