<robot
  name="elfin10" xmlns:xacro="http://www.ros.org/wiki/xacro">
  
  <xacro:include filename="$(find elfin_description)/urdf/materials.xacro" />
  
  <xacro:include filename="$(find elfin_description)/urdf/elfin_robot.gazebo" />
  
  <xacro:include filename="$(find elfin_description)/urdf/elfin_transmission.xacro" />
  
  <xacro:property name="PI" value="3.1415926535897931"/>
  
  <xacro:property name="density" value="3.09"/>
  
  <link name="world"/>
  
  <joint name="world_base" type="fixed">
    <origin
      xyz="0 0 0"
      rpy="0 0 0" />
    <parent
      link="world" />
    <child
      link="elfin_base_link" />
  </joint>
  
   <link name="elfin_base_link"/>
  
  <joint name="elfin_base_joint" type="fixed">
    <origin
      xyz="0 0 0"
      rpy="0 0 ${PI/2}" />
    <parent
      link="elfin_base_link" />
    <child
      link="elfin_base" />
  </joint>

   <link
    name="elfin_base">
    <inertial>
      <origin
        xyz="0.000308998351988781 0.00273575090066537 0.0272874749978871"
        rpy="0 0 0" />
      <mass
        value="0.885425214033795" />
      <inertia
        ixx="0.00268610674383135"
        ixy="1.61497641153452E-05"
        ixz="3.72959384780042E-06"
        iyy="0.00301073326471619"
        iyz="3.90037941387144E-05"
        izz="0.00520494004071148" />
    </inertial>
    <visual>
      <origin
        xyz="0 0 0"
        rpy="0 0 0" />
      <geometry>
        <mesh
          filename="package://elfin_description/meshes/elfin10/elfin_base_link.STL" />
      </geometry>
      <material
        name="">
        <color
          rgba="1 1 1 1" />
      </material>
    </visual>
    <collision>
      <origin
        xyz="0 0 0"
        rpy="0 0 0" />
      <geometry>
        <mesh
          filename="package://elfin_description/meshes/elfin10/elfin_base_link.STL" />
      </geometry>
    </collision>
  </link>

  <link
    name="elfin_link1">
    <inertial>
      <origin
        xyz="-0.0256023262243377 -1.62602847268471E-05 0.0821397524271189"
        rpy="0 0 0" />
      <mass
        value="5.0666551243434" />
      <inertia
        ixx="0.038977097970591"
        ixy="6.08838549359665E-06"
        ixz="0.00975553606854457"
        iyy="0.0431999258303973"
        iyz="2.92439974857155E-06"
        izz="0.0198076858553278" />
    </inertial>
    <visual>
      <origin
        xyz="0 0 0"
        rpy="0 0 0" />
      <geometry>
        <mesh
          filename="package://elfin_description/meshes/elfin10/elfin_link1.STL" />
      </geometry>
      <material
        name="">
        <color
          rgba="1 1 1 1" />
      </material>
    </visual>
    <collision>
      <origin
        xyz="0 0 0"
        rpy="0 0 0" />
      <geometry>
        <mesh
          filename="package://elfin_description/meshes/elfin10/elfin_link1.STL" />
      </geometry>
    </collision>
  </link>
  <joint
    name="elfin_joint1"
    type="revolute">
    <origin
      xyz="0 0 0.1135"
      rpy="0 0 0" />
    <parent
      link="elfin_base" />
    <child
      link="elfin_link1" />
    <axis
      xyz="0 0 1" />
    <limit
      lower="-3.14"
      upper="3.14"
      effort="420"
      velocity="1.57" />
  </joint>
  <link
    name="elfin_link2">
    <inertial>
      <origin
        xyz="-0.00733875204652666 -0.203204758586133 0.0410958376319429"
        rpy="0 0 0" />
      <mass
        value="1.67187821121901" />
      <inertia
        ixx="0.0439464748772139"
        ixy="-9.56963727666492E-06"
        ixz="-5.81264740217952E-07"
        iyy="0.00419748327993436"
        iyz="-0.00166261669205279"
        izz="0.0454846532898179" />
    </inertial>
    <visual>
      <origin
        xyz="0 0 0"
        rpy="0 0 0" />
      <geometry>
        <mesh
          filename="package://elfin_description/meshes/elfin10/elfin_link2.STL" />
      </geometry>
      <material
        name="">
        <color
          rgba="1 1 1 1" />
      </material>
    </visual>
    <collision>
      <origin
        xyz="0 0 0"
        rpy="0 0 0" />
      <geometry>
        <mesh
          filename="package://elfin_description/meshes/elfin10/elfin_link2.STL" />
      </geometry>
    </collision>
  </link>
  <joint
    name="elfin_joint2"
    type="revolute">
    <origin
      xyz="-0.102499985410128 0.00732886700183363 0.153244350761449"
      rpy="-1.5707963267949 0 1.5707963267949" />
    <parent
      link="elfin_link1" />
    <child
      link="elfin_link2" />
    <axis
      xyz="0 0 1" />
    <limit
      lower="-2.35"
      upper="2.35"
      effort="420"
      velocity="1.57" />
  </joint>
  <link
    name="elfin_link3">
    <inertial>
      <origin
        xyz="2.41698443355562E-05 -0.0521743520401219 -0.0560418101258959"
        rpy="0 0 0" />
      <mass
        value="2.52833871519162" />
      <inertia
        ixx="0.0139633942538435"
        ixy="-3.226921129389E-06"
        ixz="2.15712479037642E-06"
        iyy="0.00648774151674613"
        iyz="-0.00342599914450158"
        izz="0.0122349254525393" />
    </inertial>
    <visual>
      <origin
        xyz="0 0 0"
        rpy="0 0 0" />
      <geometry>
        <mesh
          filename="package://elfin_description/meshes/elfin10/elfin_link3.STL" />
      </geometry>
      <material
        name="">
        <color
          rgba="1 1 1 1" />
      </material>
    </visual>
    <collision>
      <origin
        xyz="0 0 0"
        rpy="0 0 0" />
      <geometry>
        <mesh
          filename="package://elfin_description/meshes/elfin10/elfin_link3.STL" />
      </geometry>
    </collision>
  </link>
  <joint
    name="elfin_joint3"
    type="revolute">
    <origin
      xyz="-0.00732886700183536 -0.473255648966734 -0.0245000000000048"
      rpy="0 0 0" />
    <parent
      link="elfin_link2" />
    <child
      link="elfin_link3" />
    <axis
      xyz="0 0 -1" />
    <limit
      lower="-2.61"
      upper="2.61"
      effort="200"
      velocity="1.57" />
  </joint>
  <link
    name="elfin_link4">
    <inertial>
      <origin
        xyz="-0.0655157891899572 -1.82308655212263E-05 0.15837470257518"
        rpy="0 0 0" />
      <mass
        value="0.775104782083546" />
      <inertia
        ixx="0.0114555561082403"
        ixy="2.19094484211439E-07"
        ixz="0.00266651463452"
        iyy="0.0123478082621956"
        iyz="-1.64179944498674E-06"
        izz="0.00252810456539086" />
    </inertial>
    <visual>
      <origin
        xyz="0 0 0"
        rpy="0 0 0" />
      <geometry>
        <mesh
          filename="package://elfin_description/meshes/elfin10/elfin_link4.STL" />
      </geometry>
      <material
        name="">
        <color
          rgba="1 1 1 1" />
      </material>
    </visual>
    <collision>
      <origin
        xyz="0 0 0"
        rpy="0 0 0" />
      <geometry>
        <mesh
          filename="package://elfin_description/meshes/elfin10/elfin_link4.STL" />
      </geometry>
    </collision>
  </link>
  <joint
    name="elfin_joint4"
    type="revolute">
    <origin
      xyz="0 -0.146499999728183 -0.0779999855743914"
      rpy="1.5707963267949 1.5707963267949 0" />
    <parent
      link="elfin_link3" />
    <child
      link="elfin_link4" />
    <axis
      xyz="0 0 -1" />
    <limit
      lower="-3.14"
      upper="3.14"
      effort="200"
      velocity="1.57" />
  </joint>
  <link
    name="elfin_link5">
    <inertial>
      <origin
        xyz="-7.53559402678653E-06 -0.0377654754034753 -0.047491241533565"
        rpy="0 0 0" />
      <mass
        value="1.07928561350228" />
      <inertia
        ixx="0.00347298936695168"
        ixy="-2.54068509779172E-07"
        ixz="-5.75046752801039E-07"
        iyy="0.00165141038810566"
        iyz="-0.000859338032022029"
        izz="0.00288851541818101" />
    </inertial>
    <visual>
      <origin
        xyz="0 0 0"
        rpy="0 0 0" />
      <geometry>
        <mesh
          filename="package://elfin_description/meshes/elfin10/elfin_link5.STL" />
      </geometry>
      <material
        name="">
        <color
          rgba="1 1 1 1" />
      </material>
    </visual>
    <collision>
      <origin
        xyz="0 0 0"
        rpy="0 0 0" />
      <geometry>
        <mesh
          filename="package://elfin_description/meshes/elfin10/elfin_link5.STL" />
      </geometry>
    </collision>
  </link>
  <joint
    name="elfin_joint5"
    type="revolute">
    <origin
      xyz="-0.0649999930247983 0 0.373499977225244"
      rpy="-1.5707963267949 0 1.5707963267949" />
    <parent
      link="elfin_link4" />
    <child
      link="elfin_link5" />
    <axis
      xyz="0 0 -1" />
    <limit
      lower="-2.56"
      upper="2.56"
      effort="69"
      velocity="1.57" />
  </joint>
  <link
    name="elfin_link6">
    <inertial>
      <origin
        xyz="-0.00817384445024986 9.28078187108763E-05 0.0394638017467175"
        rpy="0 0 0" />
      <mass
        value="0.119882046423882" />
      <inertia
        ixx="8.12013652521768E-05"
        ixy="2.08687521048734E-07"
        ixz="-2.2234968672821E-06"
        iyy="8.35696503343738E-05"
        iyz="1.10054365931951E-09"
        izz="0.000140099518584709" />
    </inertial>
    <visual>
      <origin
        xyz="0 0 0"
        rpy="0 0 0" />
      <geometry>
        <mesh
          filename="package://elfin_description/meshes/elfin10/elfin_link6.STL" />
      </geometry>
      <material
        name="">
        <color
          rgba="1 1 1 1" />
      </material>
    </visual>
    <collision>
      <origin
        xyz="0 0 0"
        rpy="0 0 0" />
      <geometry>
        <mesh
          filename="package://elfin_description/meshes/elfin10/elfin_link6.STL" />
      </geometry>
    </collision>
  </link>
  <joint
    name="elfin_joint6"
    type="revolute">
    <origin
      xyz="0 -0.105 -0.065"
      rpy="1.5708 1.5708 0" />
    <parent
      link="elfin_link5" />
    <child
      link="elfin_link6" />
    <axis
      xyz="0 0 1" />
    <limit
      lower="-3.14"
      upper="3.14"
      effort="69"
      velocity="1.57" />
  </joint>

   <link name="elfin_end_link"/>

  <joint
    name="elfin_end_joint"
    type="fixed">
    <origin
      xyz="-0.000370495118397286 0.000153464102833181 0.0629999999999997"
      rpy="0 0 -0.0122082043644551" />
    <parent
      link="elfin_link6" />
    <child
      link="elfin_end_link" />
  </joint>
  
  <link name="elfin_dummy_gripper"/>
  
  <joint name="elfin_dummy_joint" type="fixed">
    <origin
      xyz="0 0.109 0"
      rpy="${-PI/2} ${-PI/2} 0" />
    <parent
      link="elfin_link6" />
    <child
      link="elfin_dummy_gripper" />
  </joint>
  
</robot>
