<robot
  name="elfin10" xmlns:xacro="http://www.ros.org/wiki/xacro">
  
  <xacro:include filename="$(find elfin_description)/urdf/materials.xacro" />
  
  <xacro:include filename="$(find elfin_description)/urdf/elfin_robot.gazebo" />
  
  <xacro:include filename="$(find elfin_description)/urdf/elfin_transmission.xacro" />
  
  <xacro:property name="PI" value="3.1415926535897931"/>
  
  <link name="world"/>
  
  <joint name="world_base" type="fixed">
    <origin
      xyz="0 0 0"
      rpy="0 0 0" />
    <parent
      link="world" />
    <child
      link="elfin_base_link" />
  </joint>
  
  <link name="elfin_base_link"/>
  
  <joint name="elfin_base_joint" type="fixed">
    <origin
      xyz="0 0 0"
      rpy="0 0 ${PI/2}" />
    <parent
      link="elfin_base_link" />
    <child
      link="elfin_base" />
  </joint>
  
  <link
    name="elfin_base">
    <inertial>
      <origin
        xyz="0.000308020598430213 0.027286204143835 -0.00272949562920981"
        rpy="0 0 0" />
      <mass value="0.05"/>
      <inertia
	  ixx="0.001" ixy="0.0" ixz="0.0"
	  iyy="0.001" iyz="0.0"
	  izz="0.001"/>
    </inertial>
    <visual>
      <origin
        xyz="0 0 0"
        rpy="0 0 0" />
      <geometry>
        <mesh
          filename="package://elfin_description/meshes/elfin10/elfin_base.STL" />
      </geometry>
      <material
        name="metal_white"/>
    </visual>
    <collision>
      <origin
        xyz="0 0 0"
        rpy="0 0 0" />
      <geometry>
        <mesh
          filename="package://elfin_description/meshes/elfin10/elfin_base.STL" />
      </geometry>
    </collision>
  </link>
  <link
    name="elfin_link1">
    <inertial>
      <origin
        xyz="-0.025606009350082 0.195630799437867 1.98466916955487E-05"
        rpy="0 0 0" />
      <mass value="0.05"/>
      <inertia
	  ixx="0.001" ixy="0.0" ixz="0.0"
	  iyy="0.001" iyz="0.0"
	  izz="0.001"/>
    </inertial>
    <visual>
      <origin
        xyz="0 0 0"
        rpy="0 0 0" />
      <geometry>
        <mesh
          filename="package://elfin_description/meshes/elfin10/elfin_link1.STL" />
      </geometry>
      <material
        name="metal"/>
    </visual>
    <collision>
      <origin
        xyz="0 0 0"
        rpy="0 0 0" />
      <geometry>
        <mesh
          filename="package://elfin_description/meshes/elfin10/elfin_link1.STL" />
      </geometry>
    </collision>
  </link>
  <joint
    name="elfin_joint1"
    type="revolute">
    <origin
      xyz="0 0 0"
      rpy="${PI/2} 0 0" />
    <parent
      link="elfin_base" />
    <child
      link="elfin_link1" />
    <axis
      xyz="0 1 0" />
    <limit
      lower="-3.14"
      upper="3.14"
      effort="420"
      velocity="1.57" />
  </joint>
  <link
    name="elfin_link2">
    <inertial>
      <origin
        xyz="-0.059127689307098 0.209937989447816 7.56723981552217E-06"
        rpy="0 0 0" />
      <mass value="0.05"/>
      <inertia
	  ixx="0.001" ixy="0.0" ixz="0.0"
	  iyy="0.001" iyz="0.0"
	  izz="0.001"/>
    </inertial>
    <visual>
      <origin
        xyz="0 0 0"
        rpy="0 0 0" />
      <geometry>
        <mesh
          filename="package://elfin_description/meshes/elfin10/elfin_link2.STL" />
      </geometry>
      <material
        name="metal_grey"/>
    </visual>
    <collision>
      <origin
        xyz="0 0 0"
        rpy="0 0 0" />
      <geometry>
        <mesh
          filename="package://elfin_description/meshes/elfin10/elfin_link2.STL" />
      </geometry>
    </collision>
  </link>
  <joint
    name="elfin_joint2"
    type="revolute">
    <origin
      xyz="-0.084469 0.26 0"
      rpy="0 0 0" />
    <parent
      link="elfin_link1" />
    <child
      link="elfin_link2" />
    <axis
      xyz="-1 0 0" />
    <limit
      lower="-2.35"
      upper="2.35"
      effort="420"
      velocity="1.57" />
  </joint>
  <link
    name="elfin_link3">
    <inertial>
      <origin
        xyz="0.0625123989669429 -0.052176807477553 2.64760976133438E-05"
        rpy="0 0 0" />
      <mass value="0.05"/>
      <inertia
	  ixx="0.001" ixy="0.0" ixz="0.0"
	  iyy="0.001" iyz="0.0"
	  izz="0.001"/>
    </inertial>
    <visual>
      <origin
        xyz="0 0 0"
        rpy="0 0 0" />
      <geometry>
        <mesh
          filename="package://elfin_description/meshes/elfin10/elfin_link3.STL" />
      </geometry>
      <material
        name="metal"/>
    </visual>
    <collision>
      <origin
        xyz="0 0 0"
        rpy="0 0 0" />
      <geometry>
        <mesh
          filename="package://elfin_description/meshes/elfin10/elfin_link3.STL" />
      </geometry>
    </collision>
  </link>
  <joint
    name="elfin_joint3"
    type="revolute">
    <origin
      xyz="0 0.48 0"
      rpy="${PI} 0 0" />
    <parent
      link="elfin_link2" />
    <child
      link="elfin_link3" />
    <axis
      xyz="1 0 0" />
    <limit
      lower="-2.61"
      upper="2.61"
      effort="200"
      velocity="1.57" />
  </joint>
  <link
    name="elfin_link4">
    <inertial>
      <origin
        xyz="-0.0655191412736019 0.17921070701944 1.42681979805022E-05"
        rpy="0 0 0" />
      <mass value="0.05"/>
      <inertia
	  ixx="0.001" ixy="0.0" ixz="0.0"
	  iyy="0.001" iyz="0.0"
	  izz="0.001"/>
    </inertial>
    <visual>
      <origin
        xyz="0 0 0"
        rpy="0 0 0" />
      <geometry>
        <mesh
          filename="package://elfin_description/meshes/elfin10/elfin_link4.STL" />
      </geometry>
      <material
        name="metal_grey"/>
    </visual>
    <collision>
      <origin
        xyz="0 0 0"
        rpy="0 0 0" />
      <geometry>
        <mesh
          filename="package://elfin_description/meshes/elfin10/elfin_link4.STL" />
      </geometry>
    </collision>
  </link>
  <joint
    name="elfin_joint4"
    type="revolute">
    <origin
      xyz="0.084469 -0.12571 0"
      rpy="${-PI} 0 0" />
    <parent
      link="elfin_link3" />
    <child
      link="elfin_link4" />
    <axis
      xyz="0 1 0" />
    <limit
      lower="-3.14"
      upper="3.14"
      effort="200"
      velocity="1.57" />
  </joint>
  <link
    name="elfin_link5">
    <inertial>
      <origin
        xyz="-0.0175084997767369 -0.0377654900394784 -7.04779685984352E-06"
        rpy="0 0 0" />
      <mass value="0.05"/>
      <inertia
	  ixx="0.001" ixy="0.0" ixz="0.0"
	  iyy="0.001" iyz="0.0"
	  izz="0.001"/>
    </inertial>
    <visual>
      <origin
        xyz="0 0 0"
        rpy="0 0 0" />
      <geometry>
        <mesh
          filename="package://elfin_description/meshes/elfin10/elfin_link5.STL" />
      </geometry>
      <material
        name="metal"/>
    </visual>
    <collision>
      <origin
        xyz="0 0 0"
        rpy="0 0 0" />
      <geometry>
        <mesh
          filename="package://elfin_description/meshes/elfin10/elfin_link5.STL" />
      </geometry>
    </collision>
  </link>
  <joint
    name="elfin_joint5"
    type="revolute">
    <origin
      xyz="0 0.39429 0"
      rpy="${-PI} 0 0" />
    <parent
      link="elfin_link4" />
    <child
      link="elfin_link5" />
    <axis
      xyz="1 0 0" />
    <limit
      lower="-2.56"
      upper="2.56"
      effort="69"
      velocity="1.57" />
  </joint>
  <link
    name="elfin_link6">
    <inertial>
      <origin
        xyz="-0.0412046461038743 -0.870077360796272 -0.000195877685084774"
        rpy="0 0 0" />
      <mass value="0.05"/>
      <inertia
	  ixx="0.001" ixy="0.0" ixz="0.0"
	  iyy="0.001" iyz="0.0"
	  izz="0.001"/>
    </inertial>
    <visual>
      <origin
        xyz="0 0 0"
        rpy="0 0 0" />
      <geometry>
        <mesh
          filename="package://elfin_description/meshes/elfin10/elfin_link6.STL" />
      </geometry>
      <material
        name="metal_white"/>
    </visual>
    <collision>
      <origin
        xyz="0 0 0"
        rpy="0 0 0" />
      <geometry>
        <mesh
          filename="package://elfin_description/meshes/elfin10/elfin_link6.STL" />
      </geometry>
    </collision>
  </link>
  <joint
    name="elfin_joint6"
    type="revolute">
    <origin
      xyz="0 -0.111 0"
      rpy="${PI} 0 0" />
    <parent
      link="elfin_link5" />
    <child
      link="elfin_link6" />
    <axis
      xyz="0 1 0" />
    <limit
      lower="-3.14"
      upper="3.14"
      effort="69"
      velocity="1.57" />
  </joint>
  
  <link name="elfin_end_link"/>
  
  <joint name="elfin_end_joint" type="fixed">
    <origin
      xyz="0 0.089 0"
      rpy="${-PI/2} ${-PI/2} 0" />
    <parent
      link="elfin_link6" />
    <child
      link="elfin_end_link" />
  </joint>
  
  <link name="elfin_dummy_gripper"/>
  
  <joint name="elfin_dummy_joint" type="fixed">
    <origin
      xyz="0 0.109 0"
      rpy="${-PI/2} ${-PI/2} 0" />
    <parent
      link="elfin_link6" />
    <child
      link="elfin_dummy_gripper" />
  </joint>
  
</robot>
